<?xml version="1.0" ?>
<robot xmlns:xacro="http://ros.org/wiki/xacro">

  <!-- right leg -->
  <xacro:macro name="rhphumanoid_r_leg" params="parent">

  <!-- right hip yaw joint -->
  <joint name="r_hip_yaw" type="revolute">
    <parent link="${parent}"/>
    <child link="r_hip_yaw_link"/>
    <origin xyz="0.017000 -0.034930 -0.045670" rpy="0 0 0" />
    <axis xyz="0 0 -1" />
    <limit effort="${45*9.80665/100}" velocity="${(pi/3)/0.18}" lower="${-pi*2/3}" upper="${pi*2/3}" />
    <dynamics damping="0.1" friction="0.0" />
  </joint>
  <!-- <xacro:insert_transmission name="r_hip_yaw" /> -->

  <!-- right hip yaw link -->
  <link name="r_hip_yaw_link">
    <visual>
      <xacro:insert_mesh_r_hip_yaw_link />
    </visual>
    <collision>
      <xacro:insert_mesh_r_hip_yaw_link />
    </collision>
    <!-- <collision>
      <origin xyz="0 0 0" rpy="0 0 0"/>
      <geometry>
        <box size="0 0 0"/>
      </geometry>
    </collision> -->
    <inertial>
      <xacro:insert_inertia_r_hip_yaw_link />
    </inertial>
  </link>

  <!-- right hip roll joint -->
  <joint name="r_hip_roll" type="revolute">
    <parent link="r_hip_yaw_link"/>
    <child link="r_hip_roll_link"/>
    <origin xyz="-0.015830 0.000000 -0.035400" rpy="0 0 0" />
    <axis xyz="-1 0 0" />
    <limit effort="${45*9.80665/100}" velocity="${(pi/3)/0.18}" lower="${-pi*2/3}" upper="${pi*2/3}" />
    <dynamics damping="0.1" friction="0.0" />
  </joint>
  <!-- <xacro:insert_transmission name="r_hip_roll" /> -->

  <!-- right hip roll link -->
  <link name="r_hip_roll_link">
    <visual>
      <xacro:insert_mesh_r_hip_roll_link />
    </visual>
    <collision>
      <xacro:insert_mesh_r_hip_roll_link />
    </collision>
    <!-- <collision>
      <origin xyz="0 0 0" rpy="0 0 0"/>
      <geometry>
        <box size="0 0 0"/>
      </geometry>
    </collision> -->
    <inertial>
      <xacro:insert_inertia_r_hip_roll_link />
    </inertial>
  </link>

  <!-- right hip pitch joint -->
  <joint name="r_hip_pitch" type="revolute">
    <parent link="r_hip_roll_link"/>
    <child link="r_hip_pitch_link"/>
    <origin xyz="0.016330 -0.025420 0.000000" rpy="0 0 0" />
    <axis xyz="0 -1 0" />
    <limit effort="${45*9.80665/100}" velocity="${(pi/3)/0.18}" lower="${-pi*2/3}" upper="${pi*2/3}" />
    <dynamics damping="0.1" friction="0.0" />
  </joint>
  <!-- <xacro:insert_transmission name="r_hip_pitch" /> -->

  <!-- right hip pitch link -->
  <link name="r_hip_pitch_link">
    <visual>
      <xacro:insert_mesh_r_hip_pitch_link />
    </visual>
    <collision>
      <xacro:insert_mesh_r_hip_pitch_link />
    </collision>
    <!-- <collision>
      <origin xyz="0 0 0" rpy="0 0 0"/>
      <geometry>
        <box size="0 0 0"/>
      </geometry>
    </collision> -->
    <inertial>
      <xacro:insert_inertia_r_hip_pitch_link />
    </inertial>
  </link>

  <!-- right knee joint -->
  <joint name="r_knee" type="revolute">
    <parent link="r_hip_pitch_link"/>
    <child link="r_knee_link"/>
    <origin xyz="0.000000 0.000000 -0.072100" rpy="0 0 0" />
    <axis xyz="0 -1 0" />
    <limit effort="${45*9.80665/100}" velocity="${(pi/3)/0.18}" lower="${-pi*2/3}" upper="${pi*2/3}" />
    <dynamics damping="0.1" friction="0.0" />
  </joint>
  <!-- <xacro:insert_transmission name="r_knee" /> -->

  <!-- right knee link -->
  <link name="r_knee_link">
    <visual>
      <xacro:insert_mesh_r_knee_link />
    </visual>
    <collision>
      <xacro:insert_mesh_r_knee_link />
    </collision>
    <!-- <collision>
      <origin xyz="0 0 0" rpy="0 0 0"/>
      <geometry>
        <box size="0 0 0"/>
      </geometry>
    </collision> -->
    <inertial>
      <xacro:insert_inertia_r_knee_link />
    </inertial>
  </link>

  <!-- right ankle pitch joint -->
  <joint name="r_ank_pitch" type="revolute">
    <parent link="r_knee_link"/>
    <child link="r_ank_pitch_link"/>
    <origin xyz="0.000000 0.000000 -0.072100" rpy="0 0 0" />
    <axis xyz="0 1 0" />
    <limit effort="${45*9.80665/100}" velocity="${(pi/3)/0.18}" lower="${-pi*2/3}" upper="${pi*2/3}" />
    <dynamics damping="0.1" friction="0.0" />
  </joint>
  <!-- <xacro:insert_transmission name="r_ank_pitch" /> -->

  <!-- right ankle pitch link -->
  <link name="r_ank_pitch_link">
    <visual>
      <xacro:insert_mesh_r_ank_pitch_link />
    </visual>
    <collision>
      <xacro:insert_mesh_r_ank_pitch_link />
    </collision>
    <!-- <collision>
      <origin xyz="0 0 0" rpy="0 0 0"/>
      <geometry>
        <box size="0 0 0"/>
      </geometry>
    </collision> -->
    <inertial>
      <xacro:insert_inertia_r_ank_pitch_link />
    </inertial>
  </link>

  <!-- right ankle roll joint -->
  <joint name="r_ank_roll" type="revolute">
    <parent link="r_ank_pitch_link"/>
    <child link="r_ank_roll_link"/>
    <origin xyz="-0.016330 0.025420 0.000000" rpy="0 0 0" />
    <axis xyz="1 0 0" />
    <limit effort="${45*9.80665/100}" velocity="${(pi/3)/0.18}" lower="${-pi*2/3}" upper="${pi*2/3}" />
    <dynamics damping="0.1" friction="0.0" />
  </joint>
  <!-- <xacro:insert_transmission name="r_ank_roll" /> -->

  <!-- right ankle roll link -->
  <link name="r_ank_roll_link">
    <visual>
      <xacro:insert_mesh_r_ank_roll_link />
    </visual>
    <collision>
      <xacro:insert_mesh_r_ank_roll_link />
    </collision>
    <!-- <collision>
      <origin xyz="0 0 0" rpy="0 0 0"/>
      <geometry>
        <box size="0 0 0"/>
      </geometry>
    </collision> -->
    <inertial>
      <xacro:insert_inertia_r_ank_roll_link />
    </inertial>
  </link>

  </xacro:macro>

</robot>
